<?xml version="1.0"?>

<robot xmlns:xacro="http://ros.org/wiki/xacro">

    <xacro:macro name="drive_wheel" params="prefix parent y_reflect">
        <link name="${prefix}_drive_wheel_link">
            <visual>
                <origin xyz="0 0 0" rpy="1.57 0 0"/>
                <geometry>
                    <cylinder length="${wheel_width}" radius="${wheel_radius}"/>
                </geometry>
            </visual>

            <inertial>
                <mass value="5"/>
                <origin xyz=" 0 0 0" rpy="0 0 0" />
                <inertia ixx="0.0206" ixy="0" ixz="0"
                        iyx="0" iyy="0.0390" iyz="0"
                        izx="0" izy="0" izz="0.0206" />   
            </inertial>            

            <collision>
                <origin xyz="0 0 0" rpy="1.57 0 0"/>
                <geometry>
                    <!-- <cylinder length="${wheel_width}" radius="${wheel_radius}"/> -->
                    <sphere radius="${wheel_radius}"/>
                </geometry>
            </collision>
        </link>
        <gazebo reference="${prefix}_drive_wheel_link">
            <material>Gazebo/Red</material>
            <!-- friction -->
            <!-- <mu1>100</mu1>
            <mu2>100</mu2> -->
            <!-- stiffness -->
            <!-- <kp>10000000</kp>
            <kd>10000000</kd> -->
        </gazebo>

        <joint name="${prefix}_drive_wheel_joint" type="continuous">
            <parent link="${parent}"/>
            <child link="${prefix}_drive_wheel_link"/>
            <!-- <origin xyz="0 ${y_reflect * (wheel_width/2 + wheel_yoff)} 0" rpy="0 0 0"/> -->
            <origin xyz="0 ${y_reflect * wheel_yoff} 0" rpy="0 0 0"/>
            <axis xyz="0 1 0"/>
            <limit effort="1000" velocity="1000"/>
            <!-- <dynamics damping="1.0" friction="10.0"/> -->
        </joint>

    </xacro:macro>

</robot>